<?xml version="1.0" encoding="utf-8"?>
<!-- This URDF was automatically created by SolidWorks to URDF Exporter! Originally created by Stephen Brawner (brawner@gmail.com) 
     Commit Version: 1.6.0-1-g15f4949  Build Version: 1.6.7594.29634
     For more information, please see http://wiki.ros.org/sw_urdf_exporter -->

<robot xmlns:xacro="http://ros.org/wiki/xacro" name="skeleton">

  <xacro:macro name="rotating_base" >

    <link name="base_frame">
        <origin xyz="0.0 0.0 0.0" rpy="0.0 0.0 0.0"/>
    </link>

    <link name="base_link">
        <origin xyz="0.0 0.0 0.0" rpy="0.0 0.0 0.0"/>
        <visual>
            <origin rpy="0 0 0" xyz="0 0 0.025"/>
            <geometry>
                <cylinder length="0.05" radius="0.3"/>
            </geometry>
        </visual>
        <visual>
            <origin rpy="0 0 0" xyz="0.025 0 0.15"/>
            <geometry>
                <box size="0.05 0.1 0.2"/>
            </geometry>
        </visual>
        <collision>
            <geometry>
                <cylinder length="0.05" radius="0.025"/>
            <origin rpy="0 0 0" xyz="0 0 0"/>
            </geometry>
        </collision>
        <inertial>
            <mass value="0.1"/>
            <inertia ixx="0.067" ixy="0.0" ixz="0.0" iyy="0.067" iyz="0.0" izz="0.035"/>
        </inertial>

    </link>

    <joint name="mounting" type="fixed">
        <origin xyz="0.0 0.0 0.0" rpy="0.0 0.0 0.0"/>
        <parent link="base_frame"/>
        <child link="base_link"/>  
    </joint>

    <link name="inter_1">
        <origin xyz="0.0 0.0 0.0" rpy="0.0 0.0 0.0"/>

        <visual>
        <origin rpy="0 0 0" xyz="-0.025 0.1 0"/>
        <geometry>
                <box size="0.05 0.1 0.2"/>
        </geometry>
        <material name="yellow">
            <color rgba="1 1 0 1"/>
        </material>
        </visual>

        <visual>
            <origin rpy="0 0 0" xyz="-0.0250 0 -0.05"/>
            <geometry>
                <box size="0.05 0.1 0.1"/>
            </geometry>
        </visual>

        <visual>
            <origin rpy="0 0 0" xyz="0.025 0.1 0.05"/>
            <geometry>
                <box size = "0.05 0.1 0.1"/>
            </geometry>
        </visual>
        <inertial>
            <mass value="0.1"/>
            <inertia ixx="0.067" ixy="0.0" ixz="0.0" iyy="0.067" iyz="0.0" izz="0.035"/>
        </inertial>
    </link>

    <joint name="rev_1" type="revolute">
        <origin xyz="0 0 0.25" rpy="0 0 0 "/>
        <parent link= "base_link"/>
        <child link = "inter_1"/>
        <axis xyz="1 0 0"/>
        <limit effort="30" velocity="1.0" lower="-0.45" upper="0.45" />
    </joint>
  </xacro:macro>



</robot>